[2023-06-07 10:30:51,317][src.utils][INFO] - Git sha: a78aae517535a9760211e71ffc591118b750a75c
[2023-06-07 10:30:51,333][src.utils][INFO] - Changed files: ['src/evals/sequence_completion.py']
[2023-06-07 10:30:51,351][src.utils][INFO] - Git diff:
diff --git a/src/evals/sequence_completion.py b/src/evals/sequence_completion.py
index a44cbe6..27c3ac5 100644
--- a/src/evals/sequence_completion.py
+++ b/src/evals/sequence_completion.py
@@ -149,10 +149,10 @@ def sequence_completion_equality(
             "sequence": sequence,
             "generated_completion_rule": explanation,
             "generated_completion": actual_completion,
-            "generated_completion_matches": None,
+            "generated_completion_matches": False,
             "model_self_consistency_evaluation": consistency_resp,
             "model_completion": model_completion_resp,
-            "model_completion_matches": None,
+            "model_completion_matches": False,
         }

     last_completion = eval(explanation)(last_completion_step + 1)
[2023-06-07 10:30:51,353][src.utils][INFO] - Changed directory to /Users/domenicrosati/src/introspective-self-consistency/results/2023-06-07-09-46-35/compute_dependence_with_base_changes=False,sequence_completion_capability.model=gpt-3.5-turbo,sequence_completion_equality=False,string_transformation_completion_equality=False/evaluate_sequence_completion_capability
[2023-06-07 10:30:51,353][src.evals.sequence_completion_capability][INFO] - Evaluating sequence completion capability...
[2023-06-07 10:30:58,363][src.evals.sequence_completion_capability][ERROR] - invalid syntax (<string>, line 1)
Traceback (most recent call last):
  File "/Users/domenicrosati/src/introspective-self-consistency/src/evals/sequence_completion_capability.py", line 110, in evaluate_sequence_completion_capability
    sequence_completion_eval(
  File "/Users/domenicrosati/src/introspective-self-consistency/src/evals/sequence_completion_capability.py", line 69, in sequence_completion_eval
    completion = eval(explanation)(i)
  File "<string>", line 1
    This sequence is generated by the recurrence relation:
         ^^^^^^^^
SyntaxError: invalid syntax
[2023-06-07 10:30:58,363][src.evals.sequence_completion_capability][WARNING] - invalid syntax (<string>, line 1)
[2023-06-07 10:31:01,536][src.evals.sequence_completion_capability][ERROR] - maximum recursion depth exceeded in comparison
Traceback (most recent call last):
  File "/Users/domenicrosati/src/introspective-self-consistency/src/evals/sequence_completion_capability.py", line 110, in evaluate_sequence_completion_capability
    sequence_completion_eval(
  File "/Users/domenicrosati/src/introspective-self-consistency/src/evals/sequence_completion_capability.py", line 69, in sequence_completion_eval
    completion = eval(explanation)(i)
  File "<string>", line 1, in <lambda>
  File "<string>", line 1, in <lambda>
  File "<string>", line 1, in <lambda>
  [Previous line repeated 982 more times]
RecursionError: maximum recursion depth exceeded in comparison
[2023-06-07 10:31:01,541][src.evals.sequence_completion_capability][WARNING] - maximum recursion depth exceeded in comparison
[2023-06-07 10:31:03,901][src.evals.sequence_completion_capability][ERROR] - maximum recursion depth exceeded in comparison
Traceback (most recent call last):
  File "/Users/domenicrosati/src/introspective-self-consistency/src/evals/sequence_completion_capability.py", line 110, in evaluate_sequence_completion_capability
    sequence_completion_eval(
  File "/Users/domenicrosati/src/introspective-self-consistency/src/evals/sequence_completion_capability.py", line 69, in sequence_completion_eval
    completion = eval(explanation)(i)
  File "<string>", line 1, in <lambda>
  File "<string>", line 1, in <lambda>
  File "<string>", line 1, in <lambda>
  [Previous line repeated 982 more times]
RecursionError: maximum recursion depth exceeded in comparison
[2023-06-07 10:31:03,907][src.evals.sequence_completion_capability][WARNING] - maximum recursion depth exceeded in comparison
[2023-06-07 10:31:18,229][src.evals.sequence_completion_capability][ERROR] - maximum recursion depth exceeded in comparison
Traceback (most recent call last):
  File "/Users/domenicrosati/src/introspective-self-consistency/src/evals/sequence_completion_capability.py", line 110, in evaluate_sequence_completion_capability
    sequence_completion_eval(
  File "/Users/domenicrosati/src/introspective-self-consistency/src/evals/sequence_completion_capability.py", line 69, in sequence_completion_eval
    completion = eval(explanation)(i)
  File "<string>", line 1, in <lambda>
  File "<string>", line 1, in <lambda>
  File "<string>", line 1, in <lambda>
  [Previous line repeated 982 more times]
RecursionError: maximum recursion depth exceeded in comparison
[2023-06-07 10:31:18,233][src.evals.sequence_completion_capability][WARNING] - maximum recursion depth exceeded in comparison
[2023-06-07 10:31:29,294][src.evals.sequence_completion_capability][ERROR] - invalid syntax (<string>, line 1)
Traceback (most recent call last):
  File "/Users/domenicrosati/src/introspective-self-consistency/src/evals/sequence_completion_capability.py", line 110, in evaluate_sequence_completion_capability
    sequence_completion_eval(
  File "/Users/domenicrosati/src/introspective-self-consistency/src/evals/sequence_completion_capability.py", line 69, in sequence_completion_eval
    completion = eval(explanation)(i)
  File "<string>", line 1
    This sequence can be generated using the following formula:
         ^^^^^^^^
SyntaxError: invalid syntax
[2023-06-07 10:31:29,294][src.evals.sequence_completion_capability][WARNING] - invalid syntax (<string>, line 1)
[2023-06-07 10:32:04,356][openai][INFO] - error_code=None error_message='That model is currently overloaded with other requests. You can retry your request, or contact us through our help center at help.openai.com if the error persists. (Please include the request ID 42d98e0b281814e7de445d0dcf70f9e5 in your message.)' error_param=None error_type=server_error message='OpenAI API error received' stream_error=False
[2023-06-07 10:32:04,356][src.evals.sequence_completion_capability][ERROR] - That model is currently overloaded with other requests. You can retry your request, or contact us through our help center at help.openai.com if the error persists. (Please include the request ID 42d98e0b281814e7de445d0dcf70f9e5 in your message.)
Traceback (most recent call last):
  File "/Users/domenicrosati/src/introspective-self-consistency/src/evals/sequence_completion_capability.py", line 110, in evaluate_sequence_completion_capability
    sequence_completion_eval(
  File "/Users/domenicrosati/src/introspective-self-consistency/src/evals/sequence_completion_capability.py", line 54, in sequence_completion_eval
    explanation_resp = generate_response_with_turns(
  File "/Users/domenicrosati/src/introspective-self-consistency/src/models/completions.py", line 21, in generate_response_with_turns
    return openai_model.generate_response_with_turns(
  File "/Users/domenicrosati/src/introspective-self-consistency/src/models/openai_model.py", line 151, in generate_response_with_turns
    return generate_chat_completion(
  File "/Users/domenicrosati/src/introspective-self-consistency/src/models/openai_model.py", line 108, in generate_chat_completion
    response = openai.ChatCompletion.create(
  File "/Users/domenicrosati/.asdf/installs/python/3.10.4/lib/python3.10/site-packages/openai/api_resources/chat_completion.py", line 25, in create
    return super().create(*args, **kwargs)
  File "/Users/domenicrosati/.asdf/installs/python/3.10.4/lib/python3.10/site-packages/openai/api_resources/abstract/engine_api_resource.py", line 153, in create
    response, _, api_key = requestor.request(
  File "/Users/domenicrosati/.asdf/installs/python/3.10.4/lib/python3.10/site-packages/openai/api_requestor.py", line 226, in request
    resp, got_stream = self._interpret_response(result, stream)
  File "/Users/domenicrosati/.asdf/installs/python/3.10.4/lib/python3.10/site-packages/openai/api_requestor.py", line 619, in _interpret_response
    self._interpret_response_line(
  File "/Users/domenicrosati/.asdf/installs/python/3.10.4/lib/python3.10/site-packages/openai/api_requestor.py", line 682, in _interpret_response_line
    raise self.handle_error_response(
openai.error.RateLimitError: That model is currently overloaded with other requests. You can retry your request, or contact us through our help center at help.openai.com if the error persists. (Please include the request ID 42d98e0b281814e7de445d0dcf70f9e5 in your message.)
[2023-06-07 10:32:04,365][src.evals.sequence_completion_capability][WARNING] - That model is currently overloaded with other requests. You can retry your request, or contact us through our help center at help.openai.com if the error persists. (Please include the request ID 42d98e0b281814e7de445d0dcf70f9e5 in your message.)
[2023-06-07 10:32:17,799][src.evals.sequence_completion_capability][ERROR] - maximum recursion depth exceeded in comparison
Traceback (most recent call last):
  File "/Users/domenicrosati/src/introspective-self-consistency/src/evals/sequence_completion_capability.py", line 110, in evaluate_sequence_completion_capability
    sequence_completion_eval(
  File "/Users/domenicrosati/src/introspective-self-consistency/src/evals/sequence_completion_capability.py", line 69, in sequence_completion_eval
    completion = eval(explanation)(i)
  File "<string>", line 1, in <lambda>
  File "<string>", line 1, in <lambda>
  File "<string>", line 1, in <lambda>
  [Previous line repeated 982 more times]
RecursionError: maximum recursion depth exceeded in comparison
[2023-06-07 10:32:17,804][src.evals.sequence_completion_capability][WARNING] - maximum recursion depth exceeded in comparison
[2023-06-07 10:32:24,628][src.evals.sequence_completion_capability][ERROR] - invalid syntax (<string>, line 1)
Traceback (most recent call last):
  File "/Users/domenicrosati/src/introspective-self-consistency/src/evals/sequence_completion_capability.py", line 110, in evaluate_sequence_completion_capability
    sequence_completion_eval(
  File "/Users/domenicrosati/src/introspective-self-consistency/src/evals/sequence_completion_capability.py", line 69, in sequence_completion_eval
    completion = eval(explanation)(i)
  File "<string>", line 1
    This sequence is generated by the recursive formula:
         ^^^^^^^^
SyntaxError: invalid syntax
[2023-06-07 10:32:24,628][src.evals.sequence_completion_capability][WARNING] - invalid syntax (<string>, line 1)
[2023-06-07 10:32:26,592][src.evals.sequence_completion_capability][ERROR] - invalid syntax (<string>, line 1)
Traceback (most recent call last):
  File "/Users/domenicrosati/src/introspective-self-consistency/src/evals/sequence_completion_capability.py", line 110, in evaluate_sequence_completion_capability
    sequence_completion_eval(
  File "/Users/domenicrosati/src/introspective-self-consistency/src/evals/sequence_completion_capability.py", line 69, in sequence_completion_eval
    completion = eval(explanation)(i)
  File "<string>", line 1
    lambda x: 1 for any value of x.
                ^^^
SyntaxError: invalid syntax
[2023-06-07 10:32:26,592][src.evals.sequence_completion_capability][WARNING] - invalid syntax (<string>, line 1)
[2023-06-07 10:32:29,704][src.evals.sequence_completion_capability][ERROR] - invalid syntax (<string>, line 1)
Traceback (most recent call last):
  File "/Users/domenicrosati/src/introspective-self-consistency/src/evals/sequence_completion_capability.py", line 110, in evaluate_sequence_completion_capability
    sequence_completion_eval(
  File "/Users/domenicrosati/src/introspective-self-consistency/src/evals/sequence_completion_capability.py", line 69, in sequence_completion_eval
    completion = eval(explanation)(i)
  File "<string>", line 1
    This sequence does not seem to follow a simple arithmetic or geometric pattern. It may be a result of a more complex formula or algorithm.
         ^^^^^^^^
SyntaxError: invalid syntax
[2023-06-07 10:32:29,705][src.evals.sequence_completion_capability][WARNING] - invalid syntax (<string>, line 1)
[2023-06-07 10:32:33,406][src.evals.sequence_completion_capability][ERROR] - invalid syntax (<string>, line 1)
Traceback (most recent call last):
  File "/Users/domenicrosati/src/introspective-self-consistency/src/evals/sequence_completion_capability.py", line 110, in evaluate_sequence_completion_capability
    sequence_completion_eval(
  File "/Users/domenicrosati/src/introspective-self-consistency/src/evals/sequence_completion_capability.py", line 69, in sequence_completion_eval
    completion = eval(explanation)(i)
  File "<string>", line 1
    This sequence is not an arithmetic or geometric sequence. It is not possible to generate this sequence with a simple formula.
         ^^^^^^^^
SyntaxError: invalid syntax
[2023-06-07 10:32:33,406][src.evals.sequence_completion_capability][WARNING] - invalid syntax (<string>, line 1)
[2023-06-07 10:32:38,819][src.evals.sequence_completion_capability][ERROR] - maximum recursion depth exceeded in comparison
Traceback (most recent call last):
  File "/Users/domenicrosati/src/introspective-self-consistency/src/evals/sequence_completion_capability.py", line 110, in evaluate_sequence_completion_capability
    sequence_completion_eval(
  File "/Users/domenicrosati/src/introspective-self-consistency/src/evals/sequence_completion_capability.py", line 69, in sequence_completion_eval
    completion = eval(explanation)(i)
  File "<string>", line 1, in <lambda>
  File "<string>", line 1, in <lambda>
  File "<string>", line 1, in <lambda>
  [Previous line repeated 982 more times]
RecursionError: maximum recursion depth exceeded in comparison
[2023-06-07 10:32:38,824][src.evals.sequence_completion_capability][WARNING] - maximum recursion depth exceeded in comparison
[2023-06-07 10:32:48,952][src.evals.sequence_completion_capability][ERROR] - maximum recursion depth exceeded in comparison
Traceback (most recent call last):
  File "/Users/domenicrosati/src/introspective-self-consistency/src/evals/sequence_completion_capability.py", line 110, in evaluate_sequence_completion_capability
    sequence_completion_eval(
  File "/Users/domenicrosati/src/introspective-self-consistency/src/evals/sequence_completion_capability.py", line 69, in sequence_completion_eval
    completion = eval(explanation)(i)
  File "<string>", line 1, in <lambda>
  File "<string>", line 1, in <lambda>
  File "<string>", line 1, in <lambda>
  [Previous line repeated 982 more times]
RecursionError: maximum recursion depth exceeded in comparison
[2023-06-07 10:32:48,957][src.evals.sequence_completion_capability][WARNING] - maximum recursion depth exceeded in comparison
[2023-06-07 10:32:51,064][src.evals.sequence_completion_capability][ERROR] - maximum recursion depth exceeded in comparison
Traceback (most recent call last):
  File "/Users/domenicrosati/src/introspective-self-consistency/src/evals/sequence_completion_capability.py", line 110, in evaluate_sequence_completion_capability
    sequence_completion_eval(
  File "/Users/domenicrosati/src/introspective-self-consistency/src/evals/sequence_completion_capability.py", line 69, in sequence_completion_eval
    completion = eval(explanation)(i)
  File "<string>", line 1, in <lambda>
  File "<string>", line 1, in <lambda>
  File "<string>", line 1, in <lambda>
  [Previous line repeated 982 more times]
RecursionError: maximum recursion depth exceeded in comparison
[2023-06-07 10:32:51,069][src.evals.sequence_completion_capability][WARNING] - maximum recursion depth exceeded in comparison
[2023-06-07 10:33:26,326][openai][INFO] - error_code=None error_message='That model is currently overloaded with other requests. You can retry your request, or contact us through our help center at help.openai.com if the error persists. (Please include the request ID 060b78a9eed1d8c78aa08846d962b489 in your message.)' error_param=None error_type=server_error message='OpenAI API error received' stream_error=False
[2023-06-07 10:33:26,326][src.evals.sequence_completion_capability][ERROR] - That model is currently overloaded with other requests. You can retry your request, or contact us through our help center at help.openai.com if the error persists. (Please include the request ID 060b78a9eed1d8c78aa08846d962b489 in your message.)
Traceback (most recent call last):
  File "/Users/domenicrosati/src/introspective-self-consistency/src/evals/sequence_completion_capability.py", line 110, in evaluate_sequence_completion_capability
    sequence_completion_eval(
  File "/Users/domenicrosati/src/introspective-self-consistency/src/evals/sequence_completion_capability.py", line 54, in sequence_completion_eval
    explanation_resp = generate_response_with_turns(
  File "/Users/domenicrosati/src/introspective-self-consistency/src/models/completions.py", line 21, in generate_response_with_turns
    return openai_model.generate_response_with_turns(
  File "/Users/domenicrosati/src/introspective-self-consistency/src/models/openai_model.py", line 151, in generate_response_with_turns
    return generate_chat_completion(
  File "/Users/domenicrosati/src/introspective-self-consistency/src/models/openai_model.py", line 108, in generate_chat_completion
    response = openai.ChatCompletion.create(
  File "/Users/domenicrosati/.asdf/installs/python/3.10.4/lib/python3.10/site-packages/openai/api_resources/chat_completion.py", line 25, in create
    return super().create(*args, **kwargs)
  File "/Users/domenicrosati/.asdf/installs/python/3.10.4/lib/python3.10/site-packages/openai/api_resources/abstract/engine_api_resource.py", line 153, in create
    response, _, api_key = requestor.request(
  File "/Users/domenicrosati/.asdf/installs/python/3.10.4/lib/python3.10/site-packages/openai/api_requestor.py", line 226, in request
    resp, got_stream = self._interpret_response(result, stream)
  File "/Users/domenicrosati/.asdf/installs/python/3.10.4/lib/python3.10/site-packages/openai/api_requestor.py", line 619, in _interpret_response
    self._interpret_response_line(
  File "/Users/domenicrosati/.asdf/installs/python/3.10.4/lib/python3.10/site-packages/openai/api_requestor.py", line 682, in _interpret_response_line
    raise self.handle_error_response(
openai.error.RateLimitError: That model is currently overloaded with other requests. You can retry your request, or contact us through our help center at help.openai.com if the error persists. (Please include the request ID 060b78a9eed1d8c78aa08846d962b489 in your message.)
[2023-06-07 10:33:26,327][src.evals.sequence_completion_capability][WARNING] - That model is currently overloaded with other requests. You can retry your request, or contact us through our help center at help.openai.com if the error persists. (Please include the request ID 060b78a9eed1d8c78aa08846d962b489 in your message.)
[2023-06-07 10:33:50,451][src.evals.sequence_completion_capability][ERROR] - invalid syntax (<string>, line 1)
Traceback (most recent call last):
  File "/Users/domenicrosati/src/introspective-self-consistency/src/evals/sequence_completion_capability.py", line 110, in evaluate_sequence_completion_capability
    sequence_completion_eval(
  File "/Users/domenicrosati/src/introspective-self-consistency/src/evals/sequence_completion_capability.py", line 69, in sequence_completion_eval
    completion = eval(explanation)(i)
  File "<string>", line 1
    This sequence is generated by the formula:
         ^^^^^^^^
SyntaxError: invalid syntax
[2023-06-07 10:33:50,451][src.evals.sequence_completion_capability][WARNING] - invalid syntax (<string>, line 1)
[2023-06-07 10:34:21,627][openai][INFO] - error_code=None error_message='That model is currently overloaded with other requests. You can retry your request, or contact us through our help center at help.openai.com if the error persists. (Please include the request ID 096a3ba6231dada47813c5bc1fec8ff2 in your message.)' error_param=None error_type=server_error message='OpenAI API error received' stream_error=False
[2023-06-07 10:34:21,628][src.evals.sequence_completion_capability][ERROR] - That model is currently overloaded with other requests. You can retry your request, or contact us through our help center at help.openai.com if the error persists. (Please include the request ID 096a3ba6231dada47813c5bc1fec8ff2 in your message.)
Traceback (most recent call last):
  File "/Users/domenicrosati/src/introspective-self-consistency/src/evals/sequence_completion_capability.py", line 110, in evaluate_sequence_completion_capability
    sequence_completion_eval(
  File "/Users/domenicrosati/src/introspective-self-consistency/src/evals/sequence_completion_capability.py", line 51, in sequence_completion_eval
    completion_resp = generate_response_with_turns(
  File "/Users/domenicrosati/src/introspective-self-consistency/src/models/completions.py", line 21, in generate_response_with_turns
    return openai_model.generate_response_with_turns(
  File "/Users/domenicrosati/src/introspective-self-consistency/src/models/openai_model.py", line 151, in generate_response_with_turns
    return generate_chat_completion(
  File "/Users/domenicrosati/src/introspective-self-consistency/src/models/openai_model.py", line 108, in generate_chat_completion
    response = openai.ChatCompletion.create(
  File "/Users/domenicrosati/.asdf/installs/python/3.10.4/lib/python3.10/site-packages/openai/api_resources/chat_completion.py", line 25, in create
    return super().create(*args, **kwargs)
  File "/Users/domenicrosati/.asdf/installs/python/3.10.4/lib/python3.10/site-packages/openai/api_resources/abstract/engine_api_resource.py", line 153, in create
    response, _, api_key = requestor.request(
  File "/Users/domenicrosati/.asdf/installs/python/3.10.4/lib/python3.10/site-packages/openai/api_requestor.py", line 226, in request
    resp, got_stream = self._interpret_response(result, stream)
  File "/Users/domenicrosati/.asdf/installs/python/3.10.4/lib/python3.10/site-packages/openai/api_requestor.py", line 619, in _interpret_response
    self._interpret_response_line(
  File "/Users/domenicrosati/.asdf/installs/python/3.10.4/lib/python3.10/site-packages/openai/api_requestor.py", line 682, in _interpret_response_line
    raise self.handle_error_response(
openai.error.RateLimitError: That model is currently overloaded with other requests. You can retry your request, or contact us through our help center at help.openai.com if the error persists. (Please include the request ID 096a3ba6231dada47813c5bc1fec8ff2 in your message.)
[2023-06-07 10:34:21,629][src.evals.sequence_completion_capability][WARNING] - That model is currently overloaded with other requests. You can retry your request, or contact us through our help center at help.openai.com if the error persists. (Please include the request ID 096a3ba6231dada47813c5bc1fec8ff2 in your message.)
[2023-06-07 10:34:27,674][src.evals.sequence_completion_capability][INFO] -
        Evaluated 122 ambiguous sequences of 139 total.
        Resulting in:
        - 53.0% rules_matches_sequence
        - 84.0% completion_is_correct
